Error inesperado en Deutsche Bank: Object of type UUID is not JSON serializable
Traceback (most recent call last):
  File "/project/workspace/api/sct/services.py", line 195, in deutsche_bank_transfer
    response = requests.post(url, json=SepaCreditTransferRequest, headers=headers)
               ^^^^^^^^^^^^^^^^^^^^^^^^^^^^^^^^^^^^^^^^^^^^^^^^^^^^^^^^^^^^^^^^^^^
  File "/project/workspace/.venv/lib/python3.11/site-packages/requests/api.py", line 115, in post
    return request("post", url, data=data, json=json, **kwargs)
           ^^^^^^^^^^^^^^^^^^^^^^^^^^^^^^^^^^^^^^^^^^^^^^^^^^^^
  File "/project/workspace/.venv/lib/python3.11/site-packages/requests/api.py", line 59, in request
    return session.request(method=method, url=url, **kwargs)
           ^^^^^^^^^^^^^^^^^^^^^^^^^^^^^^^^^^^^^^^^^^^^^^^^^
  File "/project/workspace/.venv/lib/python3.11/site-packages/requests/sessions.py", line 575, in request
    prep = self.prepare_request(req)
           ^^^^^^^^^^^^^^^^^^^^^^^^^
  File "/project/workspace/.venv/lib/python3.11/site-packages/requests/sessions.py", line 484, in prepare_request
    p.prepare(
  File "/project/workspace/.venv/lib/python3.11/site-packages/requests/models.py", line 370, in prepare
    self.prepare_body(data, files, json)
  File "/project/workspace/.venv/lib/python3.11/site-packages/requests/models.py", line 510, in prepare_body
    body = complexjson.dumps(json, allow_nan=False)
           ^^^^^^^^^^^^^^^^^^^^^^^^^^^^^^^^^^^^^^^^
  File "/usr/local/lib/python3.11/json/__init__.py", line 238, in dumps
    **kw).encode(obj)
          ^^^^^^^^^^^
  File "/usr/local/lib/python3.11/json/encoder.py", line 200, in encode
    chunks = self.iterencode(o, _one_shot=True)
             ^^^^^^^^^^^^^^^^^^^^^^^^^^^^^^^^^^
  File "/usr/local/lib/python3.11/json/encoder.py", line 258, in iterencode
    return _iterencode(o, 0)
           ^^^^^^^^^^^^^^^^^
  File "/usr/local/lib/python3.11/json/encoder.py", line 180, in default
    raise TypeError(f'Object of type {o.__class__.__name__} '
TypeError: Object of type UUID is not JSON serializable

---------------------------------

ERROR 2025-04-12 19:31:24,411 middleware Error en /app/sct/list5/: 'SCTList5View' object has no attribute 'object_list'
Traceback (most recent call last):
  File "/project/workspace/.venv/lib/python3.11/site-packages/django/core/handlers/base.py", line 197, in _get_response
    response = wrapped_callback(request, *callback_args, **callback_kwargs)
               ^^^^^^^^^^^^^^^^^^^^^^^^^^^^^^^^^^^^^^^^^^^^^^^^^^^^^^^^^^^^
  File "/project/workspace/.venv/lib/python3.11/site-packages/django/views/generic/base.py", line 104, in view
    return self.dispatch(request, *args, **kwargs)
           ^^^^^^^^^^^^^^^^^^^^^^^^^^^^^^^^^^^^^^^
  File "/project/workspace/.venv/lib/python3.11/site-packages/django/views/generic/base.py", line 143, in dispatch
    return handler(request, *args, **kwargs)
           ^^^^^^^^^^^^^^^^^^^^^^^^^^^^^^^^^
  File "/project/workspace/.venv/lib/python3.11/site-packages/django/views/generic/edit.py", line 182, in post
    return super().post(request, *args, **kwargs)
           ^^^^^^^^^^^^^^^^^^^^^^^^^^^^^^^^^^^^^^
  File "/project/workspace/.venv/lib/python3.11/site-packages/django/views/generic/edit.py", line 151, in post
    return self.form_valid(form)
           ^^^^^^^^^^^^^^^^^^^^^
  File "/project/workspace/api/sct/views.py", line 262, in form_valid
    return self.form_invalid(form)
           ^^^^^^^^^^^^^^^^^^^^^^^
  File "/project/workspace/.venv/lib/python3.11/site-packages/django/views/generic/edit.py", line 67, in form_invalid
    return self.render_to_response(self.get_context_data(form=form))
                                   ^^^^^^^^^^^^^^^^^^^^^^^^^^^^^^^^
  File "/project/workspace/api/sct/views.py", line 247, in get_context_data
    context = super().get_context_data(**kwargs)
              ^^^^^^^^^^^^^^^^^^^^^^^^^^^^^^^^^^
  File "/project/workspace/.venv/lib/python3.11/site-packages/django/views/generic/edit.py", line 73, in get_context_data
    return super().get_context_data(**kwargs)
           ^^^^^^^^^^^^^^^^^^^^^^^^^^^^^^^^^^
  File "/project/workspace/.venv/lib/python3.11/site-packages/django/views/generic/detail.py", line 101, in get_context_data
    return super().get_context_data(**context)
           ^^^^^^^^^^^^^^^^^^^^^^^^^^^^^^^^^^^
  File "/project/workspace/.venv/lib/python3.11/site-packages/django/views/generic/list.py", line 124, in get_context_data
    queryset = object_list if object_list is not None else self.object_list
                                                           ^^^^^^^^^^^^^^^^
AttributeError: 'SCTList5View' object has no attribute 'object_list'
ERROR 2025-04-12 19:31:24,412 log Internal Server Error: /app/sct/list5/
Traceback (most recent call last):
  File "/project/workspace/.venv/lib/python3.11/site-packages/django/core/handlers/exception.py", line 55, in inner
    response = get_response(request)
               ^^^^^^^^^^^^^^^^^^^^^
  File "/project/workspace/.venv/lib/python3.11/site-packages/django/core/handlers/base.py", line 197, in _get_response
    response = wrapped_callback(request, *callback_args, **callback_kwargs)
               ^^^^^^^^^^^^^^^^^^^^^^^^^^^^^^^^^^^^^^^^^^^^^^^^^^^^^^^^^^^^
  File "/project/workspace/.venv/lib/python3.11/site-packages/django/views/generic/base.py", line 104, in view
    return self.dispatch(request, *args, **kwargs)
           ^^^^^^^^^^^^^^^^^^^^^^^^^^^^^^^^^^^^^^^
  File "/project/workspace/.venv/lib/python3.11/site-packages/django/views/generic/base.py", line 143, in dispatch
    return handler(request, *args, **kwargs)
           ^^^^^^^^^^^^^^^^^^^^^^^^^^^^^^^^^
  File "/project/workspace/.venv/lib/python3.11/site-packages/django/views/generic/edit.py", line 182, in post
    return super().post(request, *args, **kwargs)
           ^^^^^^^^^^^^^^^^^^^^^^^^^^^^^^^^^^^^^^
  File "/project/workspace/.venv/lib/python3.11/site-packages/django/views/generic/edit.py", line 151, in post
    return self.form_valid(form)
           ^^^^^^^^^^^^^^^^^^^^^
  File "/project/workspace/api/sct/views.py", line 262, in form_valid
    return self.form_invalid(form)
           ^^^^^^^^^^^^^^^^^^^^^^^
  File "/project/workspace/.venv/lib/python3.11/site-packages/django/views/generic/edit.py", line 67, in form_invalid
    return self.render_to_response(self.get_context_data(form=form))
                                   ^^^^^^^^^^^^^^^^^^^^^^^^^^^^^^^^
  File "/project/workspace/api/sct/views.py", line 247, in get_context_data
    context = super().get_context_data(**kwargs)
              ^^^^^^^^^^^^^^^^^^^^^^^^^^^^^^^^^^
  File "/project/workspace/.venv/lib/python3.11/site-packages/django/views/generic/edit.py", line 73, in get_context_data
    return super().get_context_data(**kwargs)
           ^^^^^^^^^^^^^^^^^^^^^^^^^^^^^^^^^^
  File "/project/workspace/.venv/lib/python3.11/site-packages/django/views/generic/detail.py", line 101, in get_context_data
    return super().get_context_data(**context)
           ^^^^^^^^^^^^^^^^^^^^^^^^^^^^^^^^^^^
  File "/project/workspace/.venv/lib/python3.11/site-packages/django/views/generic/list.py", line 124, in get_context_data
    queryset = object_list if object_list is not None else self.object_list
                                                           ^^^^^^^^^^^^^^^^
AttributeError: 'SCTList5View' object has no attribute 'object_list'
ERROR 2025-04-12 19:31:24,413 basehttp "POST /app/sct/list5/ HTTP/1.1" 500 145
WARNING 2025-04-12 19:31:25,077 log Not Found: /favicon.ico
WARNING 2025-04-12 19:31:25,077 basehttp "GET /favicon.ico HTTP/1.1" 404 179
ERROR 2025-04-12 21:21:32,264 middleware Error en /app/sct/list5/: 'SCTList5View' object has no attribute 'object_list'
Traceback (most recent call last):
  File "/project/workspace/.venv/lib/python3.11/site-packages/django/core/handlers/base.py", line 197, in _get_response
    response = wrapped_callback(request, *callback_args, **callback_kwargs)
               ^^^^^^^^^^^^^^^^^^^^^^^^^^^^^^^^^^^^^^^^^^^^^^^^^^^^^^^^^^^^
  File "/project/workspace/.venv/lib/python3.11/site-packages/django/views/generic/base.py", line 104, in view
    return self.dispatch(request, *args, **kwargs)
           ^^^^^^^^^^^^^^^^^^^^^^^^^^^^^^^^^^^^^^^
  File "/project/workspace/.venv/lib/python3.11/site-packages/django/views/generic/base.py", line 143, in dispatch
    return handler(request, *args, **kwargs)
           ^^^^^^^^^^^^^^^^^^^^^^^^^^^^^^^^^
  File "/project/workspace/.venv/lib/python3.11/site-packages/django/views/generic/edit.py", line 182, in post
    return super().post(request, *args, **kwargs)
           ^^^^^^^^^^^^^^^^^^^^^^^^^^^^^^^^^^^^^^
  File "/project/workspace/.venv/lib/python3.11/site-packages/django/views/generic/edit.py", line 151, in post
    return self.form_valid(form)
           ^^^^^^^^^^^^^^^^^^^^^
  File "/project/workspace/api/sct/views.py", line 262, in form_valid
    return self.form_invalid(form)
           ^^^^^^^^^^^^^^^^^^^^^^^
  File "/project/workspace/.venv/lib/python3.11/site-packages/django/views/generic/edit.py", line 67, in form_invalid
    return self.render_to_response(self.get_context_data(form=form))
                                   ^^^^^^^^^^^^^^^^^^^^^^^^^^^^^^^^
  File "/project/workspace/api/sct/views.py", line 247, in get_context_data
    context = super().get_context_data(**kwargs)
              ^^^^^^^^^^^^^^^^^^^^^^^^^^^^^^^^^^
  File "/project/workspace/.venv/lib/python3.11/site-packages/django/views/generic/edit.py", line 73, in get_context_data
    return super().get_context_data(**kwargs)
           ^^^^^^^^^^^^^^^^^^^^^^^^^^^^^^^^^^
  File "/project/workspace/.venv/lib/python3.11/site-packages/django/views/generic/detail.py", line 101, in get_context_data
    return super().get_context_data(**context)
           ^^^^^^^^^^^^^^^^^^^^^^^^^^^^^^^^^^^
  File "/project/workspace/.venv/lib/python3.11/site-packages/django/views/generic/list.py", line 124, in get_context_data
    queryset = object_list if object_list is not None else self.object_list
                                                           ^^^^^^^^^^^^^^^^
AttributeError: 'SCTList5View' object has no attribute 'object_list'
ERROR 2025-04-12 21:21:32,265 log Internal Server Error: /app/sct/list5/
Traceback (most recent call last):
  File "/project/workspace/.venv/lib/python3.11/site-packages/django/core/handlers/exception.py", line 55, in inner
    response = get_response(request)
               ^^^^^^^^^^^^^^^^^^^^^
  File "/project/workspace/.venv/lib/python3.11/site-packages/django/core/handlers/base.py", line 197, in _get_response
    response = wrapped_callback(request, *callback_args, **callback_kwargs)
               ^^^^^^^^^^^^^^^^^^^^^^^^^^^^^^^^^^^^^^^^^^^^^^^^^^^^^^^^^^^^
  File "/project/workspace/.venv/lib/python3.11/site-packages/django/views/generic/base.py", line 104, in view
    return self.dispatch(request, *args, **kwargs)
           ^^^^^^^^^^^^^^^^^^^^^^^^^^^^^^^^^^^^^^^
  File "/project/workspace/.venv/lib/python3.11/site-packages/django/views/generic/base.py", line 143, in dispatch
    return handler(request, *args, **kwargs)
           ^^^^^^^^^^^^^^^^^^^^^^^^^^^^^^^^^
  File "/project/workspace/.venv/lib/python3.11/site-packages/django/views/generic/edit.py", line 182, in post
    return super().post(request, *args, **kwargs)
           ^^^^^^^^^^^^^^^^^^^^^^^^^^^^^^^^^^^^^^
  File "/project/workspace/.venv/lib/python3.11/site-packages/django/views/generic/edit.py", line 151, in post
    return self.form_valid(form)
           ^^^^^^^^^^^^^^^^^^^^^
  File "/project/workspace/api/sct/views.py", line 262, in form_valid
    return self.form_invalid(form)
           ^^^^^^^^^^^^^^^^^^^^^^^
  File "/project/workspace/.venv/lib/python3.11/site-packages/django/views/generic/edit.py", line 67, in form_invalid
    return self.render_to_response(self.get_context_data(form=form))
                                   ^^^^^^^^^^^^^^^^^^^^^^^^^^^^^^^^
  File "/project/workspace/api/sct/views.py", line 247, in get_context_data
    context = super().get_context_data(**kwargs)
              ^^^^^^^^^^^^^^^^^^^^^^^^^^^^^^^^^^
  File "/project/workspace/.venv/lib/python3.11/site-packages/django/views/generic/edit.py", line 73, in get_context_data
    return super().get_context_data(**kwargs)
           ^^^^^^^^^^^^^^^^^^^^^^^^^^^^^^^^^^
  File "/project/workspace/.venv/lib/python3.11/site-packages/django/views/generic/detail.py", line 101, in get_context_data
    return super().get_context_data(**context)
           ^^^^^^^^^^^^^^^^^^^^^^^^^^^^^^^^^^^
  File "/project/workspace/.venv/lib/python3.11/site-packages/django/views/generic/list.py", line 124, in get_context_data
    queryset = object_list if object_list is not None else self.object_list
                                                           ^^^^^^^^^^^^^^^^
AttributeError: 'SCTList5View' object has no attribute 'object_list'
ERROR 2025-04-12 21:21:32,266 basehttp "POST /app/sct/list5/ HTTP/1.1" 500 145
WARNING 2025-04-12 21:21:32,620 log Not Found: /favicon.ico
WARNING 2025-04-12 21:21:32,620 basehttp "GET /favicon.ico HTTP/1.1" 404 179
ERROR 2025-04-12 21:28:18,094 middleware Error en /app/sct/list5/: 'ProcessTransferView12' object has no attribute 'post'
Traceback (most recent call last):
  File "/project/workspace/.venv/lib/python3.11/site-packages/django/core/handlers/base.py", line 197, in _get_response
    response = wrapped_callback(request, *callback_args, **callback_kwargs)
               ^^^^^^^^^^^^^^^^^^^^^^^^^^^^^^^^^^^^^^^^^^^^^^^^^^^^^^^^^^^^
  File "/project/workspace/.venv/lib/python3.11/site-packages/django/views/generic/base.py", line 104, in view
    return self.dispatch(request, *args, **kwargs)
           ^^^^^^^^^^^^^^^^^^^^^^^^^^^^^^^^^^^^^^^
  File "/project/workspace/.venv/lib/python3.11/site-packages/django/views/generic/base.py", line 143, in dispatch
    return handler(request, *args, **kwargs)
           ^^^^^^^^^^^^^^^^^^^^^^^^^^^^^^^^^
  File "/project/workspace/.venv/lib/python3.11/site-packages/django/views/generic/edit.py", line 182, in post
    return super().post(request, *args, **kwargs)
           ^^^^^^^^^^^^^^^^^^^^^^^^^^^^^^^^^^^^^^
  File "/project/workspace/.venv/lib/python3.11/site-packages/django/views/generic/edit.py", line 151, in post
    return self.form_valid(form)
           ^^^^^^^^^^^^^^^^^^^^^
  File "/project/workspace/api/sct/views.py", line 257, in form_valid
    response = process_view.post(self.request, idempotency_key=transfer.idempotency_key)
               ^^^^^^^^^^^^^^^^^
AttributeError: 'ProcessTransferView12' object has no attribute 'post'
ERROR 2025-04-12 21:28:18,095 log Internal Server Error: /app/sct/list5/
Traceback (most recent call last):
  File "/project/workspace/.venv/lib/python3.11/site-packages/django/core/handlers/exception.py", line 55, in inner
    response = get_response(request)
               ^^^^^^^^^^^^^^^^^^^^^
  File "/project/workspace/.venv/lib/python3.11/site-packages/django/core/handlers/base.py", line 197, in _get_response
    response = wrapped_callback(request, *callback_args, **callback_kwargs)
               ^^^^^^^^^^^^^^^^^^^^^^^^^^^^^^^^^^^^^^^^^^^^^^^^^^^^^^^^^^^^
  File "/project/workspace/.venv/lib/python3.11/site-packages/django/views/generic/base.py", line 104, in view
    return self.dispatch(request, *args, **kwargs)
           ^^^^^^^^^^^^^^^^^^^^^^^^^^^^^^^^^^^^^^^
  File "/project/workspace/.venv/lib/python3.11/site-packages/django/views/generic/base.py", line 143, in dispatch
    return handler(request, *args, **kwargs)
           ^^^^^^^^^^^^^^^^^^^^^^^^^^^^^^^^^
  File "/project/workspace/.venv/lib/python3.11/site-packages/django/views/generic/edit.py", line 182, in post
    return super().post(request, *args, **kwargs)
           ^^^^^^^^^^^^^^^^^^^^^^^^^^^^^^^^^^^^^^
  File "/project/workspace/.venv/lib/python3.11/site-packages/django/views/generic/edit.py", line 151, in post
    return self.form_valid(form)
           ^^^^^^^^^^^^^^^^^^^^^
  File "/project/workspace/api/sct/views.py", line 257, in form_valid
    response = process_view.post(self.request, idempotency_key=transfer.idempotency_key)
               ^^^^^^^^^^^^^^^^^
AttributeError: 'ProcessTransferView12' object has no attribute 'post'
ERROR 2025-04-12 21:28:18,096 basehttp "POST /app/sct/list5/ HTTP/1.1" 500 145
