Error inesperado en Deutsche Bank: Object of type UUID is not JSON serializable
Traceback (most recent call last):
  File "/project/workspace/api/sct/services.py", line 195, in deutsche_bank_transfer
    response = requests.post(url, json=SepaCreditTransferRequest, headers=headers)
               ^^^^^^^^^^^^^^^^^^^^^^^^^^^^^^^^^^^^^^^^^^^^^^^^^^^^^^^^^^^^^^^^^^^
  File "/project/workspace/.venv/lib/python3.11/site-packages/requests/api.py", line 115, in post
    return request("post", url, data=data, json=json, **kwargs)
           ^^^^^^^^^^^^^^^^^^^^^^^^^^^^^^^^^^^^^^^^^^^^^^^^^^^^
  File "/project/workspace/.venv/lib/python3.11/site-packages/requests/api.py", line 59, in request
    return session.request(method=method, url=url, **kwargs)
           ^^^^^^^^^^^^^^^^^^^^^^^^^^^^^^^^^^^^^^^^^^^^^^^^^
  File "/project/workspace/.venv/lib/python3.11/site-packages/requests/sessions.py", line 575, in request
    prep = self.prepare_request(req)
           ^^^^^^^^^^^^^^^^^^^^^^^^^
  File "/project/workspace/.venv/lib/python3.11/site-packages/requests/sessions.py", line 484, in prepare_request
    p.prepare(
  File "/project/workspace/.venv/lib/python3.11/site-packages/requests/models.py", line 370, in prepare
    self.prepare_body(data, files, json)
  File "/project/workspace/.venv/lib/python3.11/site-packages/requests/models.py", line 510, in prepare_body
    body = complexjson.dumps(json, allow_nan=False)
           ^^^^^^^^^^^^^^^^^^^^^^^^^^^^^^^^^^^^^^^^
  File "/usr/local/lib/python3.11/json/__init__.py", line 238, in dumps
    **kw).encode(obj)
          ^^^^^^^^^^^
  File "/usr/local/lib/python3.11/json/encoder.py", line 200, in encode
    chunks = self.iterencode(o, _one_shot=True)
             ^^^^^^^^^^^^^^^^^^^^^^^^^^^^^^^^^^
  File "/usr/local/lib/python3.11/json/encoder.py", line 258, in iterencode
    return _iterencode(o, 0)
           ^^^^^^^^^^^^^^^^^
  File "/usr/local/lib/python3.11/json/encoder.py", line 180, in default
    raise TypeError(f'Object of type {o.__class__.__name__} '
TypeError: Object of type UUID is not JSON serializable

---------------------------------

ERROR 2025-04-12 19:31:24,411 middleware Error en /app/sct/list5/: 'SCTList5View' object has no attribute 'object_list'
Traceback (most recent call last):
  File "/project/workspace/.venv/lib/python3.11/site-packages/django/core/handlers/base.py", line 197, in _get_response
    response = wrapped_callback(request, *callback_args, **callback_kwargs)
               ^^^^^^^^^^^^^^^^^^^^^^^^^^^^^^^^^^^^^^^^^^^^^^^^^^^^^^^^^^^^
  File "/project/workspace/.venv/lib/python3.11/site-packages/django/views/generic/base.py", line 104, in view
    return self.dispatch(request, *args, **kwargs)
           ^^^^^^^^^^^^^^^^^^^^^^^^^^^^^^^^^^^^^^^
  File "/project/workspace/.venv/lib/python3.11/site-packages/django/views/generic/base.py", line 143, in dispatch
    return handler(request, *args, **kwargs)
           ^^^^^^^^^^^^^^^^^^^^^^^^^^^^^^^^^
  File "/project/workspace/.venv/lib/python3.11/site-packages/django/views/generic/edit.py", line 182, in post
    return super().post(request, *args, **kwargs)
           ^^^^^^^^^^^^^^^^^^^^^^^^^^^^^^^^^^^^^^
  File "/project/workspace/.venv/lib/python3.11/site-packages/django/views/generic/edit.py", line 151, in post
    return self.form_valid(form)
           ^^^^^^^^^^^^^^^^^^^^^
  File "/project/workspace/api/sct/views.py", line 262, in form_valid
    return self.form_invalid(form)
           ^^^^^^^^^^^^^^^^^^^^^^^
  File "/project/workspace/.venv/lib/python3.11/site-packages/django/views/generic/edit.py", line 67, in form_invalid
    return self.render_to_response(self.get_context_data(form=form))
                                   ^^^^^^^^^^^^^^^^^^^^^^^^^^^^^^^^
  File "/project/workspace/api/sct/views.py", line 247, in get_context_data
    context = super().get_context_data(**kwargs)
              ^^^^^^^^^^^^^^^^^^^^^^^^^^^^^^^^^^
  File "/project/workspace/.venv/lib/python3.11/site-packages/django/views/generic/edit.py", line 73, in get_context_data
    return super().get_context_data(**kwargs)
           ^^^^^^^^^^^^^^^^^^^^^^^^^^^^^^^^^^
  File "/project/workspace/.venv/lib/python3.11/site-packages/django/views/generic/detail.py", line 101, in get_context_data
    return super().get_context_data(**context)
           ^^^^^^^^^^^^^^^^^^^^^^^^^^^^^^^^^^^
  File "/project/workspace/.venv/lib/python3.11/site-packages/django/views/generic/list.py", line 124, in get_context_data
    queryset = object_list if object_list is not None else self.object_list
                                                           ^^^^^^^^^^^^^^^^
AttributeError: 'SCTList5View' object has no attribute 'object_list'
ERROR 2025-04-12 19:31:24,412 log Internal Server Error: /app/sct/list5/
Traceback (most recent call last):
  File "/project/workspace/.venv/lib/python3.11/site-packages/django/core/handlers/exception.py", line 55, in inner
    response = get_response(request)
               ^^^^^^^^^^^^^^^^^^^^^
  File "/project/workspace/.venv/lib/python3.11/site-packages/django/core/handlers/base.py", line 197, in _get_response
    response = wrapped_callback(request, *callback_args, **callback_kwargs)
               ^^^^^^^^^^^^^^^^^^^^^^^^^^^^^^^^^^^^^^^^^^^^^^^^^^^^^^^^^^^^
  File "/project/workspace/.venv/lib/python3.11/site-packages/django/views/generic/base.py", line 104, in view
    return self.dispatch(request, *args, **kwargs)
           ^^^^^^^^^^^^^^^^^^^^^^^^^^^^^^^^^^^^^^^
  File "/project/workspace/.venv/lib/python3.11/site-packages/django/views/generic/base.py", line 143, in dispatch
    return handler(request, *args, **kwargs)
           ^^^^^^^^^^^^^^^^^^^^^^^^^^^^^^^^^
  File "/project/workspace/.venv/lib/python3.11/site-packages/django/views/generic/edit.py", line 182, in post
    return super().post(request, *args, **kwargs)
           ^^^^^^^^^^^^^^^^^^^^^^^^^^^^^^^^^^^^^^
  File "/project/workspace/.venv/lib/python3.11/site-packages/django/views/generic/edit.py", line 151, in post
    return self.form_valid(form)
           ^^^^^^^^^^^^^^^^^^^^^
  File "/project/workspace/api/sct/views.py", line 262, in form_valid
    return self.form_invalid(form)
           ^^^^^^^^^^^^^^^^^^^^^^^
  File "/project/workspace/.venv/lib/python3.11/site-packages/django/views/generic/edit.py", line 67, in form_invalid
    return self.render_to_response(self.get_context_data(form=form))
                                   ^^^^^^^^^^^^^^^^^^^^^^^^^^^^^^^^
  File "/project/workspace/api/sct/views.py", line 247, in get_context_data
    context = super().get_context_data(**kwargs)
              ^^^^^^^^^^^^^^^^^^^^^^^^^^^^^^^^^^
  File "/project/workspace/.venv/lib/python3.11/site-packages/django/views/generic/edit.py", line 73, in get_context_data
    return super().get_context_data(**kwargs)
           ^^^^^^^^^^^^^^^^^^^^^^^^^^^^^^^^^^
  File "/project/workspace/.venv/lib/python3.11/site-packages/django/views/generic/detail.py", line 101, in get_context_data
    return super().get_context_data(**context)
           ^^^^^^^^^^^^^^^^^^^^^^^^^^^^^^^^^^^
  File "/project/workspace/.venv/lib/python3.11/site-packages/django/views/generic/list.py", line 124, in get_context_data
    queryset = object_list if object_list is not None else self.object_list
                                                           ^^^^^^^^^^^^^^^^
AttributeError: 'SCTList5View' object has no attribute 'object_list'
ERROR 2025-04-12 19:31:24,413 basehttp "POST /app/sct/list5/ HTTP/1.1" 500 145
WARNING 2025-04-12 19:31:25,077 log Not Found: /favicon.ico
WARNING 2025-04-12 19:31:25,077 basehttp "GET /favicon.ico HTTP/1.1" 404 179
ERROR 2025-04-12 21:21:32,264 middleware Error en /app/sct/list5/: 'SCTList5View' object has no attribute 'object_list'
Traceback (most recent call last):
  File "/project/workspace/.venv/lib/python3.11/site-packages/django/core/handlers/base.py", line 197, in _get_response
    response = wrapped_callback(request, *callback_args, **callback_kwargs)
               ^^^^^^^^^^^^^^^^^^^^^^^^^^^^^^^^^^^^^^^^^^^^^^^^^^^^^^^^^^^^
  File "/project/workspace/.venv/lib/python3.11/site-packages/django/views/generic/base.py", line 104, in view
    return self.dispatch(request, *args, **kwargs)
           ^^^^^^^^^^^^^^^^^^^^^^^^^^^^^^^^^^^^^^^
  File "/project/workspace/.venv/lib/python3.11/site-packages/django/views/generic/base.py", line 143, in dispatch
    return handler(request, *args, **kwargs)
           ^^^^^^^^^^^^^^^^^^^^^^^^^^^^^^^^^
  File "/project/workspace/.venv/lib/python3.11/site-packages/django/views/generic/edit.py", line 182, in post
    return super().post(request, *args, **kwargs)
           ^^^^^^^^^^^^^^^^^^^^^^^^^^^^^^^^^^^^^^
  File "/project/workspace/.venv/lib/python3.11/site-packages/django/views/generic/edit.py", line 151, in post
    return self.form_valid(form)
           ^^^^^^^^^^^^^^^^^^^^^
  File "/project/workspace/api/sct/views.py", line 262, in form_valid
    return self.form_invalid(form)
           ^^^^^^^^^^^^^^^^^^^^^^^
  File "/project/workspace/.venv/lib/python3.11/site-packages/django/views/generic/edit.py", line 67, in form_invalid
    return self.render_to_response(self.get_context_data(form=form))
                                   ^^^^^^^^^^^^^^^^^^^^^^^^^^^^^^^^
  File "/project/workspace/api/sct/views.py", line 247, in get_context_data
    context = super().get_context_data(**kwargs)
              ^^^^^^^^^^^^^^^^^^^^^^^^^^^^^^^^^^
  File "/project/workspace/.venv/lib/python3.11/site-packages/django/views/generic/edit.py", line 73, in get_context_data
    return super().get_context_data(**kwargs)
           ^^^^^^^^^^^^^^^^^^^^^^^^^^^^^^^^^^
  File "/project/workspace/.venv/lib/python3.11/site-packages/django/views/generic/detail.py", line 101, in get_context_data
    return super().get_context_data(**context)
           ^^^^^^^^^^^^^^^^^^^^^^^^^^^^^^^^^^^
  File "/project/workspace/.venv/lib/python3.11/site-packages/django/views/generic/list.py", line 124, in get_context_data
    queryset = object_list if object_list is not None else self.object_list
                                                           ^^^^^^^^^^^^^^^^
AttributeError: 'SCTList5View' object has no attribute 'object_list'
ERROR 2025-04-12 21:21:32,265 log Internal Server Error: /app/sct/list5/
Traceback (most recent call last):
  File "/project/workspace/.venv/lib/python3.11/site-packages/django/core/handlers/exception.py", line 55, in inner
    response = get_response(request)
               ^^^^^^^^^^^^^^^^^^^^^
  File "/project/workspace/.venv/lib/python3.11/site-packages/django/core/handlers/base.py", line 197, in _get_response
    response = wrapped_callback(request, *callback_args, **callback_kwargs)
               ^^^^^^^^^^^^^^^^^^^^^^^^^^^^^^^^^^^^^^^^^^^^^^^^^^^^^^^^^^^^
  File "/project/workspace/.venv/lib/python3.11/site-packages/django/views/generic/base.py", line 104, in view
    return self.dispatch(request, *args, **kwargs)
           ^^^^^^^^^^^^^^^^^^^^^^^^^^^^^^^^^^^^^^^
  File "/project/workspace/.venv/lib/python3.11/site-packages/django/views/generic/base.py", line 143, in dispatch
    return handler(request, *args, **kwargs)
           ^^^^^^^^^^^^^^^^^^^^^^^^^^^^^^^^^
  File "/project/workspace/.venv/lib/python3.11/site-packages/django/views/generic/edit.py", line 182, in post
    return super().post(request, *args, **kwargs)
           ^^^^^^^^^^^^^^^^^^^^^^^^^^^^^^^^^^^^^^
  File "/project/workspace/.venv/lib/python3.11/site-packages/django/views/generic/edit.py", line 151, in post
    return self.form_valid(form)
           ^^^^^^^^^^^^^^^^^^^^^
  File "/project/workspace/api/sct/views.py", line 262, in form_valid
    return self.form_invalid(form)
           ^^^^^^^^^^^^^^^^^^^^^^^
  File "/project/workspace/.venv/lib/python3.11/site-packages/django/views/generic/edit.py", line 67, in form_invalid
    return self.render_to_response(self.get_context_data(form=form))
                                   ^^^^^^^^^^^^^^^^^^^^^^^^^^^^^^^^
  File "/project/workspace/api/sct/views.py", line 247, in get_context_data
    context = super().get_context_data(**kwargs)
              ^^^^^^^^^^^^^^^^^^^^^^^^^^^^^^^^^^
  File "/project/workspace/.venv/lib/python3.11/site-packages/django/views/generic/edit.py", line 73, in get_context_data
    return super().get_context_data(**kwargs)
           ^^^^^^^^^^^^^^^^^^^^^^^^^^^^^^^^^^
  File "/project/workspace/.venv/lib/python3.11/site-packages/django/views/generic/detail.py", line 101, in get_context_data
    return super().get_context_data(**context)
           ^^^^^^^^^^^^^^^^^^^^^^^^^^^^^^^^^^^
  File "/project/workspace/.venv/lib/python3.11/site-packages/django/views/generic/list.py", line 124, in get_context_data
    queryset = object_list if object_list is not None else self.object_list
                                                           ^^^^^^^^^^^^^^^^
AttributeError: 'SCTList5View' object has no attribute 'object_list'
ERROR 2025-04-12 21:21:32,266 basehttp "POST /app/sct/list5/ HTTP/1.1" 500 145
WARNING 2025-04-12 21:21:32,620 log Not Found: /favicon.ico
WARNING 2025-04-12 21:21:32,620 basehttp "GET /favicon.ico HTTP/1.1" 404 179
ERROR 2025-04-12 21:28:18,094 middleware Error en /app/sct/list5/: 'ProcessTransferView12' object has no attribute 'post'
Traceback (most recent call last):
  File "/project/workspace/.venv/lib/python3.11/site-packages/django/core/handlers/base.py", line 197, in _get_response
    response = wrapped_callback(request, *callback_args, **callback_kwargs)
               ^^^^^^^^^^^^^^^^^^^^^^^^^^^^^^^^^^^^^^^^^^^^^^^^^^^^^^^^^^^^
  File "/project/workspace/.venv/lib/python3.11/site-packages/django/views/generic/base.py", line 104, in view
    return self.dispatch(request, *args, **kwargs)
           ^^^^^^^^^^^^^^^^^^^^^^^^^^^^^^^^^^^^^^^
  File "/project/workspace/.venv/lib/python3.11/site-packages/django/views/generic/base.py", line 143, in dispatch
    return handler(request, *args, **kwargs)
           ^^^^^^^^^^^^^^^^^^^^^^^^^^^^^^^^^
  File "/project/workspace/.venv/lib/python3.11/site-packages/django/views/generic/edit.py", line 182, in post
    return super().post(request, *args, **kwargs)
           ^^^^^^^^^^^^^^^^^^^^^^^^^^^^^^^^^^^^^^
  File "/project/workspace/.venv/lib/python3.11/site-packages/django/views/generic/edit.py", line 151, in post
    return self.form_valid(form)
           ^^^^^^^^^^^^^^^^^^^^^
  File "/project/workspace/api/sct/views.py", line 257, in form_valid
    response = process_view.post(self.request, idempotency_key=transfer.idempotency_key)
               ^^^^^^^^^^^^^^^^^
AttributeError: 'ProcessTransferView12' object has no attribute 'post'
ERROR 2025-04-12 21:28:18,095 log Internal Server Error: /app/sct/list5/
Traceback (most recent call last):
  File "/project/workspace/.venv/lib/python3.11/site-packages/django/core/handlers/exception.py", line 55, in inner
    response = get_response(request)
               ^^^^^^^^^^^^^^^^^^^^^
  File "/project/workspace/.venv/lib/python3.11/site-packages/django/core/handlers/base.py", line 197, in _get_response
    response = wrapped_callback(request, *callback_args, **callback_kwargs)
               ^^^^^^^^^^^^^^^^^^^^^^^^^^^^^^^^^^^^^^^^^^^^^^^^^^^^^^^^^^^^
  File "/project/workspace/.venv/lib/python3.11/site-packages/django/views/generic/base.py", line 104, in view
    return self.dispatch(request, *args, **kwargs)
           ^^^^^^^^^^^^^^^^^^^^^^^^^^^^^^^^^^^^^^^
  File "/project/workspace/.venv/lib/python3.11/site-packages/django/views/generic/base.py", line 143, in dispatch
    return handler(request, *args, **kwargs)
           ^^^^^^^^^^^^^^^^^^^^^^^^^^^^^^^^^
  File "/project/workspace/.venv/lib/python3.11/site-packages/django/views/generic/edit.py", line 182, in post
    return super().post(request, *args, **kwargs)
           ^^^^^^^^^^^^^^^^^^^^^^^^^^^^^^^^^^^^^^
  File "/project/workspace/.venv/lib/python3.11/site-packages/django/views/generic/edit.py", line 151, in post
    return self.form_valid(form)
           ^^^^^^^^^^^^^^^^^^^^^
  File "/project/workspace/api/sct/views.py", line 257, in form_valid
    response = process_view.post(self.request, idempotency_key=transfer.idempotency_key)
               ^^^^^^^^^^^^^^^^^
AttributeError: 'ProcessTransferView12' object has no attribute 'post'
ERROR 2025-04-12 21:28:18,096 basehttp "POST /app/sct/list5/ HTTP/1.1" 500 145
WARNING 2025-04-13 04:00:53,800 log Not Found: /favicon.ico
WARNING 2025-04-13 04:00:53,801 basehttp "GET /favicon.ico HTTP/1.1" 404 179
ERROR 2025-04-13 20:11:31,945 middleware Error processing request to /login/: no such column: authentication_customuser.date_joined
Traceback (most recent call last):
  File "/Users/amirmastermind/Desktop/testfile/config2222/.venv/lib/python3.12/site-packages/django/db/backends/utils.py", line 105, in _execute
    return self.cursor.execute(sql, params)
           ^^^^^^^^^^^^^^^^^^^^^^^^^^^^^^^^
  File "/Users/amirmastermind/Desktop/testfile/config2222/.venv/lib/python3.12/site-packages/django/db/backends/sqlite3/base.py", line 360, in execute
    return super().execute(query, params)
           ^^^^^^^^^^^^^^^^^^^^^^^^^^^^^^
sqlite3.OperationalError: no such column: authentication_customuser.date_joined

The above exception was the direct cause of the following exception:

Traceback (most recent call last):
  File "/Users/amirmastermind/Desktop/testfile/config2222/.venv/lib/python3.12/site-packages/django/core/handlers/base.py", line 197, in _get_response
    response = wrapped_callback(request, *callback_args, **callback_kwargs)
               ^^^^^^^^^^^^^^^^^^^^^^^^^^^^^^^^^^^^^^^^^^^^^^^^^^^^^^^^^^^^
  File "/Users/amirmastermind/Desktop/testfile/config2222/.venv/lib/python3.12/site-packages/django/views/generic/base.py", line 104, in view
    return self.dispatch(request, *args, **kwargs)
           ^^^^^^^^^^^^^^^^^^^^^^^^^^^^^^^^^^^^^^^
  File "/Users/amirmastermind/Desktop/testfile/config2222/.venv/lib/python3.12/site-packages/django/views/generic/base.py", line 143, in dispatch
    return handler(request, *args, **kwargs)
           ^^^^^^^^^^^^^^^^^^^^^^^^^^^^^^^^^
  File "/Users/amirmastermind/Desktop/testfile/config2222/api/views.py", line 91, in post
    user = authenticate(request, username=username, password=password)
           ^^^^^^^^^^^^^^^^^^^^^^^^^^^^^^^^^^^^^^^^^^^^^^^^^^^^^^^^^^^
  File "/Users/amirmastermind/Desktop/testfile/config2222/.venv/lib/python3.12/site-packages/django/views/decorators/debug.py", line 75, in sensitive_variables_wrapper
    return func(*func_args, **func_kwargs)
           ^^^^^^^^^^^^^^^^^^^^^^^^^^^^^^^
  File "/Users/amirmastermind/Desktop/testfile/config2222/.venv/lib/python3.12/site-packages/django/contrib/auth/__init__.py", line 114, in authenticate
    user = backend.authenticate(request, **credentials)
           ^^^^^^^^^^^^^^^^^^^^^^^^^^^^^^^^^^^^^^^^^^^^
  File "/Users/amirmastermind/Desktop/testfile/config2222/.venv/lib/python3.12/site-packages/django/contrib/auth/backends.py", line 65, in authenticate
    user = UserModel._default_manager.get_by_natural_key(username)
           ^^^^^^^^^^^^^^^^^^^^^^^^^^^^^^^^^^^^^^^^^^^^^^^^^^^^^^^
  File "/Users/amirmastermind/Desktop/testfile/config2222/.venv/lib/python3.12/site-packages/django/contrib/auth/base_user.py", line 37, in get_by_natural_key
    return self.get(**{self.model.USERNAME_FIELD: username})
           ^^^^^^^^^^^^^^^^^^^^^^^^^^^^^^^^^^^^^^^^^^^^^^^^^
  File "/Users/amirmastermind/Desktop/testfile/config2222/.venv/lib/python3.12/site-packages/django/db/models/manager.py", line 87, in manager_method
    return getattr(self.get_queryset(), name)(*args, **kwargs)
           ^^^^^^^^^^^^^^^^^^^^^^^^^^^^^^^^^^^^^^^^^^^^^^^^^^^
  File "/Users/amirmastermind/Desktop/testfile/config2222/.venv/lib/python3.12/site-packages/django/db/models/query.py", line 629, in get
    num = len(clone)
          ^^^^^^^^^^
  File "/Users/amirmastermind/Desktop/testfile/config2222/.venv/lib/python3.12/site-packages/django/db/models/query.py", line 366, in __len__
    self._fetch_all()
  File "/Users/amirmastermind/Desktop/testfile/config2222/.venv/lib/python3.12/site-packages/django/db/models/query.py", line 1935, in _fetch_all
    self._result_cache = list(self._iterable_class(self))
                         ^^^^^^^^^^^^^^^^^^^^^^^^^^^^^^^^
  File "/Users/amirmastermind/Desktop/testfile/config2222/.venv/lib/python3.12/site-packages/django/db/models/query.py", line 91, in __iter__
    results = compiler.execute_sql(
              ^^^^^^^^^^^^^^^^^^^^^
  File "/Users/amirmastermind/Desktop/testfile/config2222/.venv/lib/python3.12/site-packages/django/db/models/sql/compiler.py", line 1622, in execute_sql
    cursor.execute(sql, params)
  File "/Users/amirmastermind/Desktop/testfile/config2222/.venv/lib/python3.12/site-packages/django/db/backends/utils.py", line 79, in execute
    return self._execute_with_wrappers(
           ^^^^^^^^^^^^^^^^^^^^^^^^^^^^
  File "/Users/amirmastermind/Desktop/testfile/config2222/.venv/lib/python3.12/site-packages/django/db/backends/utils.py", line 92, in _execute_with_wrappers
    return executor(sql, params, many, context)
           ^^^^^^^^^^^^^^^^^^^^^^^^^^^^^^^^^^^^
  File "/Users/amirmastermind/Desktop/testfile/config2222/.venv/lib/python3.12/site-packages/django/db/backends/utils.py", line 100, in _execute
    with self.db.wrap_database_errors:
  File "/Users/amirmastermind/Desktop/testfile/config2222/.venv/lib/python3.12/site-packages/django/db/utils.py", line 91, in __exit__
    raise dj_exc_value.with_traceback(traceback) from exc_value
  File "/Users/amirmastermind/Desktop/testfile/config2222/.venv/lib/python3.12/site-packages/django/db/backends/utils.py", line 105, in _execute
    return self.cursor.execute(sql, params)
           ^^^^^^^^^^^^^^^^^^^^^^^^^^^^^^^^
  File "/Users/amirmastermind/Desktop/testfile/config2222/.venv/lib/python3.12/site-packages/django/db/backends/sqlite3/base.py", line 360, in execute
    return super().execute(query, params)
           ^^^^^^^^^^^^^^^^^^^^^^^^^^^^^^
django.db.utils.OperationalError: no such column: authentication_customuser.date_joined
ERROR 2025-04-13 20:11:31,967 log Internal Server Error: /login/
Traceback (most recent call last):
  File "/Users/amirmastermind/Desktop/testfile/config2222/.venv/lib/python3.12/site-packages/django/db/backends/utils.py", line 105, in _execute
    return self.cursor.execute(sql, params)
           ^^^^^^^^^^^^^^^^^^^^^^^^^^^^^^^^
  File "/Users/amirmastermind/Desktop/testfile/config2222/.venv/lib/python3.12/site-packages/django/db/backends/sqlite3/base.py", line 360, in execute
    return super().execute(query, params)
           ^^^^^^^^^^^^^^^^^^^^^^^^^^^^^^
sqlite3.OperationalError: no such column: authentication_customuser.date_joined

The above exception was the direct cause of the following exception:

Traceback (most recent call last):
  File "/Users/amirmastermind/Desktop/testfile/config2222/.venv/lib/python3.12/site-packages/django/core/handlers/exception.py", line 55, in inner
    response = get_response(request)
               ^^^^^^^^^^^^^^^^^^^^^
  File "/Users/amirmastermind/Desktop/testfile/config2222/.venv/lib/python3.12/site-packages/django/core/handlers/base.py", line 197, in _get_response
    response = wrapped_callback(request, *callback_args, **callback_kwargs)
               ^^^^^^^^^^^^^^^^^^^^^^^^^^^^^^^^^^^^^^^^^^^^^^^^^^^^^^^^^^^^
  File "/Users/amirmastermind/Desktop/testfile/config2222/.venv/lib/python3.12/site-packages/django/views/generic/base.py", line 104, in view
    return self.dispatch(request, *args, **kwargs)
           ^^^^^^^^^^^^^^^^^^^^^^^^^^^^^^^^^^^^^^^
  File "/Users/amirmastermind/Desktop/testfile/config2222/.venv/lib/python3.12/site-packages/django/views/generic/base.py", line 143, in dispatch
    return handler(request, *args, **kwargs)
           ^^^^^^^^^^^^^^^^^^^^^^^^^^^^^^^^^
  File "/Users/amirmastermind/Desktop/testfile/config2222/api/views.py", line 91, in post
    user = authenticate(request, username=username, password=password)
           ^^^^^^^^^^^^^^^^^^^^^^^^^^^^^^^^^^^^^^^^^^^^^^^^^^^^^^^^^^^
  File "/Users/amirmastermind/Desktop/testfile/config2222/.venv/lib/python3.12/site-packages/django/views/decorators/debug.py", line 75, in sensitive_variables_wrapper
    return func(*func_args, **func_kwargs)
           ^^^^^^^^^^^^^^^^^^^^^^^^^^^^^^^
  File "/Users/amirmastermind/Desktop/testfile/config2222/.venv/lib/python3.12/site-packages/django/contrib/auth/__init__.py", line 114, in authenticate
    user = backend.authenticate(request, **credentials)
           ^^^^^^^^^^^^^^^^^^^^^^^^^^^^^^^^^^^^^^^^^^^^
  File "/Users/amirmastermind/Desktop/testfile/config2222/.venv/lib/python3.12/site-packages/django/contrib/auth/backends.py", line 65, in authenticate
    user = UserModel._default_manager.get_by_natural_key(username)
           ^^^^^^^^^^^^^^^^^^^^^^^^^^^^^^^^^^^^^^^^^^^^^^^^^^^^^^^
  File "/Users/amirmastermind/Desktop/testfile/config2222/.venv/lib/python3.12/site-packages/django/contrib/auth/base_user.py", line 37, in get_by_natural_key
    return self.get(**{self.model.USERNAME_FIELD: username})
           ^^^^^^^^^^^^^^^^^^^^^^^^^^^^^^^^^^^^^^^^^^^^^^^^^
  File "/Users/amirmastermind/Desktop/testfile/config2222/.venv/lib/python3.12/site-packages/django/db/models/manager.py", line 87, in manager_method
    return getattr(self.get_queryset(), name)(*args, **kwargs)
           ^^^^^^^^^^^^^^^^^^^^^^^^^^^^^^^^^^^^^^^^^^^^^^^^^^^
  File "/Users/amirmastermind/Desktop/testfile/config2222/.venv/lib/python3.12/site-packages/django/db/models/query.py", line 629, in get
    num = len(clone)
          ^^^^^^^^^^
  File "/Users/amirmastermind/Desktop/testfile/config2222/.venv/lib/python3.12/site-packages/django/db/models/query.py", line 366, in __len__
    self._fetch_all()
  File "/Users/amirmastermind/Desktop/testfile/config2222/.venv/lib/python3.12/site-packages/django/db/models/query.py", line 1935, in _fetch_all
    self._result_cache = list(self._iterable_class(self))
                         ^^^^^^^^^^^^^^^^^^^^^^^^^^^^^^^^
  File "/Users/amirmastermind/Desktop/testfile/config2222/.venv/lib/python3.12/site-packages/django/db/models/query.py", line 91, in __iter__
    results = compiler.execute_sql(
              ^^^^^^^^^^^^^^^^^^^^^
  File "/Users/amirmastermind/Desktop/testfile/config2222/.venv/lib/python3.12/site-packages/django/db/models/sql/compiler.py", line 1622, in execute_sql
    cursor.execute(sql, params)
  File "/Users/amirmastermind/Desktop/testfile/config2222/.venv/lib/python3.12/site-packages/django/db/backends/utils.py", line 79, in execute
    return self._execute_with_wrappers(
           ^^^^^^^^^^^^^^^^^^^^^^^^^^^^
  File "/Users/amirmastermind/Desktop/testfile/config2222/.venv/lib/python3.12/site-packages/django/db/backends/utils.py", line 92, in _execute_with_wrappers
    return executor(sql, params, many, context)
           ^^^^^^^^^^^^^^^^^^^^^^^^^^^^^^^^^^^^
  File "/Users/amirmastermind/Desktop/testfile/config2222/.venv/lib/python3.12/site-packages/django/db/backends/utils.py", line 100, in _execute
    with self.db.wrap_database_errors:
  File "/Users/amirmastermind/Desktop/testfile/config2222/.venv/lib/python3.12/site-packages/django/db/utils.py", line 91, in __exit__
    raise dj_exc_value.with_traceback(traceback) from exc_value
  File "/Users/amirmastermind/Desktop/testfile/config2222/.venv/lib/python3.12/site-packages/django/db/backends/utils.py", line 105, in _execute
    return self.cursor.execute(sql, params)
           ^^^^^^^^^^^^^^^^^^^^^^^^^^^^^^^^
  File "/Users/amirmastermind/Desktop/testfile/config2222/.venv/lib/python3.12/site-packages/django/db/backends/sqlite3/base.py", line 360, in execute
    return super().execute(query, params)
           ^^^^^^^^^^^^^^^^^^^^^^^^^^^^^^
django.db.utils.OperationalError: no such column: authentication_customuser.date_joined
ERROR 2025-04-13 20:11:31,972 basehttp "POST /login/ HTTP/1.1" 500 145
WARNING 2025-04-13 20:11:32,034 log Not Found: /apple-touch-icon-precomposed.png
WARNING 2025-04-13 20:11:32,035 basehttp "GET /apple-touch-icon-precomposed.png HTTP/1.1" 404 179
WARNING 2025-04-13 20:11:32,253 log Not Found: /apple-touch-icon.png
WARNING 2025-04-13 20:11:32,254 basehttp "GET /apple-touch-icon.png HTTP/1.1" 404 179
